Traceback (most recent call last):
  File "/home/ebony/.cache/pypoetry/virtualenvs/python-template-NSau9UKb-py3.10/lib/python3.10/site-packages/discord/app_commands/commands.py", line 842, in _do_call
    return await self._callback(interaction, **params)  # type: ignore
  File "/home/ebony/programming/python/chroot/DSMC-Contest-Manager/main.py", line 489, in sync_commands
    await interaction.defer(thinking=True)
AttributeError: 'Interaction' object has no attribute 'defer'

The above exception was the direct cause of the following exception:

Traceback (most recent call last):
  File "/home/ebony/.cache/pypoetry/virtualenvs/python-template-NSau9UKb-py3.10/lib/python3.10/site-packages/discord/app_commands/tree.py", line 1248, in _call
    await command._invoke_with_namespace(interaction, namespace)
  File "/home/ebony/.cache/pypoetry/virtualenvs/python-template-NSau9UKb-py3.10/lib/python3.10/site-packages/discord/app_commands/commands.py", line 867, in _invoke_with_namespace
    return await self._do_call(interaction, transformed_values)
  File "/home/ebony/.cache/pypoetry/virtualenvs/python-template-NSau9UKb-py3.10/lib/python3.10/site-packages/discord/app_commands/commands.py", line 860, in _do_call
    raise CommandInvokeError(self, e) from e
discord.app_commands.errors.CommandInvokeError: Command 'sync' raised an exception: AttributeError: 'Interaction' object has no attribute 'defer'
